<mujoco model="LRMate">
  <worldbody>
    <geom pos="0 0 0.33" quat="1 0 0 0" type="mesh" mesh="base" contype="0" conaffinity="0"/>
    <body name="link_1" pos="0 0 0.33">
      <inertial pos="0.018591 0.0033701 -0.0770907" mass="2.39847" diaginertia="0.023318 0.0193776 0.0139142"/>
      <joint name="joint_1" pos="0 0 0" axis="0 0 1" limited="true" range="-3.14159 3.14159" />
      <geom pos="0.05 0 0" quat="0.707107 -0.707107 0 0" type="mesh" rgba="1 1 0 1" mesh="link1"/>
      <body name="link_2" pos="0.05 0 0" quat="0.707107 -0.707107 0 0">
        <inertial pos="-0.00710799 -0.132614 0.0247801" quat="0.5 0.5 0.5 0.5" mass="7.80187" diaginertia="0.207037 0.188399 0.0328972"/>
        <joint name="joint_2" pos="0 0 0" axis="0 0 1" limited="true" range="-3.14159 3.14159" />
        <geom pos="0 -0.44 0" quat="0 0.707107 -0.707107 0" type="mesh" rgba="1 1 0 1" mesh="link2"/>
        <body name="link_3" pos="0 -0.44 0" quat="0 0.707107 -0.707107 0">
          <inertial pos="0.00579313 -0.00590663 -0.0207324" quat="0.707107 0.707107 0 0" mass="2.98472" diaginertia="0.00810195 0.00798185 0.00686971"/>
          <joint name="joint_3" pos="0 0 0" axis="0 0 1" limited="true" range="-3.14159 3.14159" />
          <geom pos="0.035 0 0" quat="0.707107 -0.707107 0 0" type="mesh" rgba="1 1 0 1" mesh="link3"/>
          <body name="link_4" pos="0.035 0 0" quat="0.707107 -0.707107 0 0">
            <inertial pos="-0.000245714 0.00282241 -0.206061" quat="0.5 0.5 -0.5 0.5" mass="4.14418" diaginertia="0.053151 0.0529101 0.00570462"/>
            <joint name="joint_4" pos="0 0 0" axis="0 0 1" limited="true" range="-3.14159 3.14159" />
            <geom pos="0 0 -0.42" quat="0.707107 0.707107 0 0" type="mesh" rgba="1 1 0 1" mesh="link4"/>
            <body name="link_5" pos="0 0 -0.42" quat="0.707107 0.707107 0 0">
              <inertial pos="4.8044e-05 -0.027384 -0.00443815" mass="1.70042" diaginertia="0.00247956 0.00243755 0.00120034"/>
              <joint name="joint_5" pos="0 0 0" axis="0 0 1" limited="true" range="-3.14159 3.14159"/>
              <geom quat="0.707107 -0.707107 0 0" type="mesh" rgba="1 1 0 1" mesh="link5"/>
              <body name="link_6" quat="0.707107 -0.707107 0 0">
                <body name="camera_focus" pos="0.15 0 0.01">
                  <camera name="left_cam_focus" pos="-0.1 0 0.16" euler="0 0 0"/>
                </body>
                <inertial pos="0.0330067 0 -0.0768635" quat="0.457411 0.539236 0.539236 0.457411" mass="0.981" diaginertia="0.200291 0.200288 0.200058"/>
                <joint name="joint_6" pos="0 0 0" axis="0 0 1" limited="true" range="-3.14159 3.14159" />
                <geom pos="0 0 -0.08" quat="0 1 0 0" type="mesh" rgba="0 0 0 1" mesh="link6"/>
                <geom pos="0 0 -0.078" quat="0.5 0.5 0.5 0.5" type="mesh" mesh="sensor_hand_collision"/>
                <body name="gripper_leftfinger" pos="0 -0.025 -0.228" quat="0.707107 0.707107 0 0">
                  <inertial pos="0 0.01 0.02" mass="0.1" diaginertia="0.1 0.1 0.1"/>
                  <joint name="gripper_finger_joint1" pos="0 0 0" axis="0 0 -1" type="slide" limited="true" range="0 0.04" frictionloss="30"/>
                  <geom type="mesh" mesh="finger_collision"/>
                </body>
                <body name="gripper_rightfinger" pos="0 0.025 -0.228" quat="-0.707107 0.707107 0 0">
                  <inertial pos="0 -0.01 0.02" mass="0.1" diaginertia="0.1 0.1 0.1"/>
                  <joint name="gripper_finger_joint2" pos="0 0 0" axis="0 0 -1" type="slide" limited="true" range="0 0.04" frictionloss="30"/>
                  <geom quat="0 0 0 1" type="mesh" mesh="finger_collision"/>
                </body>
              </body>
            </body>
          </body>
        </body>
      </body>
    </body>
  </worldbody>
</mujoco>
